Workbook

Sheet Registo Ultimas atualizações
B2: DBDE
B3: Por quem e quando foi feita a última atualização dos projetos no ficheiro
C5: ÚLTIMA ATUALIZAÇÃO
B6: DBDE - LAB | C6: Quando | D6: Por Quem | E6: Total ou Parcial(1) | F6: Comentários
B7: API integration
B8: Best site & App | C8: 46175 | D8: Pedro M | E8: Total | F8: Atualização Calendário IT
B9: Core | C9: 46090 | D9: Frederico CA | E9: Total | F9: introdução de novo projeto "C2C - acesso direto"
B10: Payments & e-commerce
B11: SME financing
B14: Total ou Parcial (1): preencha de acordo com: Total: efetuada revisão/atualização em todos os projetos do LAB Parcial: efetuada revisãoi parcial do projetos do LAB

Sheet Calendário IT  
A3: Responsável | B3: Atividade | C3: User Stories Escritas | D3: Data Target Entrega ao IT | E3: Data Target Qualidade | F3: Data Target Produção
B4: New UX/UI Supply Chain Financing for Suppliers | C4: FALSE
B5: API enhanced entity registry for non-Clients (COMPprofile) (1) | C5: FALSE
B6: New website onboarding for Suppliers (non-Clients) (1) | C6: FALSE
B7: API integration on ERP – Confirming & Factoring files | C7: FALSE
B8: Factoring - Digital notifications | C8: FALSE
B9: New UI/UX Credit Details | C9: FALSE
B10: Crédito Digital Tesouraria (Phase 2) | C10: FALSE
B11: 100% Digital Account Closure | C11: FALSE
B12: Company Data Maintenance Journey – Phase 3 – Email e WFMC | C12: FALSE
B13: Company Data Maintenance journey – Phase 4 – Email e WFMC | C13: FALSE
B14: Debit Card Request | C14: FALSE
B15: CMBO – Content Management BackOffice | C15: FALSE
B16: Alertas | C16: FALSE | D16: 46081
B17: Open Banking | C17: FALSE | D17: 46096
B18: Configurações do Utilizador | C18: FALSE | D18: 46052
B19: Agendamentos | C19: FALSE | D19: 46052
B20: Cheques | C20: FALSE | D20: 46068
B21: Servicing | C21: FALSE | D21: 46052
B22: Via Verde | C22: FALSE | D22: 46068
B27: recenseamento não Clientes
B28: Encerramento e conta

Sheet Digital Breakfast Takeaways
G3: 23/04- Ultima Atualização | I3: Caracterização | K3: Azure Devops | L3: Checkpoint
B4: ID | C4: Serviço/Categoria | D4: Melhorias por abrir | E4: Origem | F4: Tipo | G4: Progresso | H4: Owner | I4: Complexidade | J4: Prioridade | K4: ID | L4: DBDE | M4: IT
C5: Digital Breakfast 1ª Sessão — 04/03/2026
B6: 1 | C6: Agenda | D6: Corrigir bug de triplicação de prestações de crédito na Agenda (ex: final de dezembro) | E6: Eduardo Ribeiro / André Cunha | F6: Bug | G6: Fechado | H6: Best Site | K6: Bug 990394 MSE | RevampFEE MVP2 | BUGS | pagamentos em triplicado na agenda | L6: TRUE | M6: TRUE
B7: 2 | C7: Autenticação | D7: Substituir ou complementar certificados digitais por métodos modernos (ex: Google Authenticator, M-Token) para agilizar login | E7: Eduardo Ribeiro / André Cunha | F7: Melhoria Funcional | G7: Standby/ Relançar com nova APP Empresas | H7: Core | L7: FALSE | M7: FALSE
B8: 3 | C8: Acessibilidade | D8: Melhorar performance e rapidez na exportação de extratos para Excel, especialmente com várias contas | E8: Eduardo Ribeiro / André Cunha | F8: Melhoria Funcional | G8: contactar cliente para validar se ok | H8: Best Site | L8: FALSE | M8: FALSE
B9: 4 | C9: Acessibilidade | D9: Automatizar envio de extratos/recibos para softwares de contabilidade (ex: TOConline), eliminando exportação manual por Empresa | E9: Eduardo Ribeiro / André Cunha | F9: Melhoria Funcional | G9: incluir revamp de alertas, contactar após | H9: Best Site | L9: FALSE | M9: FALSE
B10: 5 | C10: Pagamento por Lote | D10: Permitir upload de ficheiros Excel simples para pagamentos em lote, em alternativa ao XML (SEPA), com reconhecimento automático da Empresa de origem (benchmark: CGD) | E10: André Cunha | F10: Melhoria Funcional | G10: US já feita (reminder 21 maio) | H10: Best Site | L10: FALSE | M10: FALSE
B11: 6 | C11: Gestão de Cartões | D11: Rever emissão de cartões corporativos: - permitir emissão ágil de cartões (físicos ou virtuais) para colaboradores, com envio direto para morada do utilizador via App, sem centralização no titular | E11: André Cunha | F11: Melhoria Funcional | G11: dmpa - diogo | H11: Best Site | L11: FALSE | M11: FALSE
B12: 7 | C12: Login Multi-Empresas | D12: Permitir acesso a diferentes Empresas através de um único login (benchmark: Revolut Business) | E12: Eduardo Ribeiro / André Cunha | F12: Melhoria Funcional | G12: Em desenvolvimento DBDE | H12: Core | L12: FALSE | M12: FALSE
B13: 8 | C13: Parcerias | D13: Criar ou comunicar melhor um clube de parceiros relevantes (companhias aéreas, saúde, desporto) para Clientes Empresariais e colaboradores (benchmark: CoverFlex) ex: Revolut Plans | E13: Eduardo Ribeiro / André Cunha | F13: Melhoria Institucional | G13: Sem prioridade comercial atual, avaliar com lab de marketplace (DBD) | L13: FALSE | M13: FALSE
B14: 9 | C14: Segurança | D14: Após validação de segurança, permitir múltiplas transferências durante um período sem reinserir credenciais (benchmark: CGD com cartão matriz) | E14: Eduardo Ribeiro / André Cunha | F14: Melhoria Funcional | G14: avaliar e informar equipa de nova app empresas | H14: Best Site | L14: FALSE | M14: FALSE
C15: Digital Breakfast 2ª Sessão — 16/03/2026 | L15: FALSE | M15: FALSE
B16: 10 | C16: Recenseamento | D16: Digitalizar e agilizar o processo de agrupamento de Empresas, eliminando dependência da sucursal/gestor (cliente em espera há 6 meses; benchmark: CGD imediato, Revolut intuitivo) | E16: André Rodrigues Silva / José Seixas Vale | F16: Melhoria Funcional | G16: Em desenvolvimento DBDE(ligado com ponto 7) | H16: Core | L16: FALSE | M16: FALSE
B17: 11 | C17: Pagamento a Fornecedores | D17: Permitir partilha de beneficiários entre Empresas do mesmo grupo, evitando duplicação de trabalho | E17: André Rodrigues Silva | F17: Melhoria Funcional | G17: Sem prioridade | H17: Best Site | L17: FALSE | M17: FALSE
B18: 12 | C18: Acessibilidade | D18: Simplificar navegação para aceder a extratos de cartões pré-pagos (PDF e Excel) | E18: André Rodrigues Silva / José Seixas Vale | F18: Melhoria Frontend | G18: dmpa - diogo | H18: Best Site | L18: FALSE | M18: FALSE
B19: 13 | C19: Acessibilidade | D19: Permitir acesso a movimentos com mais de 90 dias | E19: André Rodrigues Silva / José Seixas Vale | F19: Melhoria Funcional | G19: psd2 | H19: Best Site | L19: FALSE | M19: FALSE
B20: 14 | C20: Autenticação e Certificados Digitais | D20: Resolver dificuldades de instalação de certificados digitais em Mac (Firefox) — cliente desistiu e precisou de apoio | E20: José Seixas Vale | F20: Bug | G20: BUG ABERTO por confirmar; ver com rui baixinho | H20: Core | L20: FALSE | M20: FALSE
B21: 15 | C21: Acessibilidade | D21: Melhorar descoberta de funcionalidades no site (ex: dificuldade em encontrar página de cartões pré-pagos) | E21: André Rodrigues Silva | F21: Melhoria Funcional | G21: research agendada | H21: Best Site | L21: FALSE | M21: FALSE
B22: 16 | C22: Cartões Pré-Pagos | D22: Permitir plafonds ajustáveis nos cartões pré-pagos à medida da necessidade, em vez de teto máximo fixo | E22: André Rodrigues Silva | F22: Melhoria Funcional | G22: dmpa - diogo | H22: Best Site | L22: FALSE | M22: FALSE
B23: 17 | C23: Gestão de Roles / Permissões | D23: Implementar gestão flexível de roles (contabilista, administrador, operador) com gestão autónoma de autorizações (benchmark: Revolut Business) | E23: José Seixas Vale | F23: Melhoria Funcional | G23: incorporar/avaliar no revamp registo de empresas | H23: Core | L23: FALSE | M23: FALSE
B24: 18 | C24: OCR / Pagamentos | D24: Implementar OCR dinâmico para deteção automática de IBAN, montante e campos ao submeter faturas | E24: José Seixas Vale | F24: Melhoria Funcional | G24: Standby/ Relançar com nova APP Empresas | H24: Best Site | L24: FALSE | M24: FALSE
B25: 19 | C25: Agenda (Renomeação/UX) | D25: Renomear "Agenda" para "Previsão de Tesouraria"; renomear "Agendamentos" para "Operações Agendadas" e incluir todas as operações como débitos diretos e serviços de dívida | E25: André Rodrigues Silva / José Seixas Vale | F25: Melhoria Frontend | G25: Relançado já com feedback de DB | H25: Best Site | L25: FALSE | M25: FALSE
B26: 20 | C26: Notificações | D26: Cada nova operação pendente deve gerar notificação com número de operações pendentes, com possibilidade de customizar alertas | E26: André Rodrigues Silva / José Seixas Vale | F26: Melhoria Funcional | G26: Previsto; avaliar/mostrar proposta com clientes | H26: Best Site | L26: FALSE | M26: FALSE
L27: FALSE | M27: FALSE

Sheet Calendário IT
A2: Projeto | B2: Janeiro | C2: Fevereiro | D2: Março | E2: Abril | F2: Maio | G2: Junho | H2: Julho | I2: Agosto | J2: Setembro | K2: Outubro | L2: Novembro | M2: Dezembro
A3: Confirming | B3: Certificação | C3: Certificação | D3: Produção
A4: Consulta de créditos | B4: Certificação | C4: Certificação | D4: Produção | Q4: Em Research
A5: CDT - Valor Alternativo | B5: Certificação | C5: Certificação | D5: Certificação | Q5: Em Design (Bliss)
A6: Recenseamento não clientes | B6: Desenvolvimento IT | C6: Certificação | D6: Certificação | E6: Em Design (Bliss) | Q6: Em Escrita
A7: Transformação dos IML´s para 5512 | B7: User Stories | C7: Desenvolvimento IT | D7: Desenvolvimento IT | E7: Produção | Q7: User Stories
A8: Modo de envio Ime|Urgente | B8: User Stories | C8: Desenvolvimento IT | D8: Desenvolvimento IT | E8: Produção | Q8: User Stories Escritas
A9: Cliente Aplauso | B9: User Stories | C9: Desenvolvimento IT | D9: Desenvolvimento IT | E9: Desenvolvimento IT | F9: Desenvolvimento IT | G9: Desenvolvimento IT | Q9: Desenvolvimento IT
A10: Encerramento de conta digital | B10: Desenvolvimento IT | C10: Desenvolvimento IT | D10: Desenvolvimento IT | E10: Produção | Q10: Certificação
A11: Pedido de cartão de crédito (email) | B11: Desenvolvimento IT | C11: Desenvolvimento IT | D11: Desenvolvimento IT | E11: Desenvolvimento IT | Q11: Produção
A12: Cartões - A NOSSA OFERTA | B12: Desenvolvimento IT | C12: Desenvolvimento IT | D12: Desenvolvimento IT | E12: Desenvolvimento IT
A13: SAF-T - Upload de ficheiro | B13: User Stories | C13: User Stories | D13: Desenvolvimento IT | E13: Certificação
A14: Agenda 2.0 | B14: Em Escrita | C14: User Stories | D14: Em Research | E14: Em Research | F14: Em Research | G14: Em Research
A15: Projeto KAFKA | B15: Em Escrita | C15: Em Escrita | D15: User Stories | E15: Desenvolvimento IT
A16: Crédito Digital Avançar (Wave 1) | B16: Em Escrita | C16: Em Escrita | D16: User Stories | E16: User Stories
A17: Via Verde | B17: Em Escrita | C17: Em Escrita | D17: Desenvolvimento IT | E17: Desenvolvimento IT | F17: Desenvolvimento IT | G17: Desenvolvimento IT
A18: Factoring - Digital notifications | B18: Em Escrita | C18: Em Escrita | D18: User Stories | E18: User Stories
A19: Requisição de Cheques | B19: Em Research | C19: Em Escrita | D19: User Stories Escritas | E19: User Stories Escritas | F19: Desenvolvimento IT | G19: Desenvolvimento IT
A20: B2B Millennium API | B20: Em Research | C20: Em Escrita | D20: Em Design (Bliss) | E20: User Stories | F20: User Stories Escritas | G20: User Stories Escritas
A21: Pedido de cartão de débito (E2E) | B21: User Stories | C21: User Stories | D21: User Stories | E21: User Stories
A22: PayByMillennium | B22: Em Escrita | C22: Em Escrita | D22: Em Escrita | E22: Em Research
A23: Cartões Servicing | B23: Em Escrita | C23: Em Escrita | D23: Em Escrita | E23: Em Research
A24: Criação de Utilizadores (Operadores) | B24: Em Escrita | C24: Em Escrita | D24: User Stories | E24: User Stories
A25: Certificado Digital | B25: Em Escrita | C25: Em Escrita | D25: User Stories | E25: User Stories
A26: M Certificados | B26: Em Escrita | C26: Em Escrita | D26: Em Escrita | E26: Em Research
A27: Open Banking | B27: Em Research | C27: Em Research | D27: Em Research | E27: Em Design (Bliss) | F27: User Stories | G27: User Stories Escritas
A28: Retornos de Ficheiros | B28: Em Research | C28: Em Research | D28: Em Escrita | E28: Em Escrita
A29: M Autenticator | B29: Em Research | C29: Em Research | D29: Em Research | E29: Em Research
A30: Registo e Recenseamento | B30: Em Research | C30: Em Research | D30: Em Research | E30: Em Research
A31: Pesquisador | B31: Em Research | C31: Em Research | D31: Em Research | E31: Em Research
A32: Nova Montra /Jornadas Meios de Recebimento | E32: Em Research | F32: Em Design (Bliss) | G32: User Stories Escritas

Sheet PRIORIDADES DBDE
B2: Maio/Junho
B3: Prioridade | C3: Projeto/Melhoria | D3: Lab | E3: Estado
B4: 10 | C4: B2B | Alteração do Protocolo da Mensagem | Alteração da Mensagem de SOAP para REST | D4: API Integration Lab
B5: 20 | C5: B2B | Serviço de Consulta de detalhe de movimentos de devolução | D5: API Integration Lab
B6: 30 | C6: B2B | REST - Consulta de Saldos e Movimentos de Conta | D6: API Integration Lab
B7: 40 | C7: B2B | REST - Confirmação do NIF do proprietário do IBAN (ConfirmationCOPB) | D7: API Integration Lab
B8: 50 | C8: B2B | Criação na PSDC | Criação de entrada do serviço ConfirmationCOPB | D8: API Integration Lab
B9: 60 | C9: B2B | REST - Ordem de Transferência Nacional Pontual / Agendada | D9: API Integration Lab
B10: 70 | C10: B2B | REST - Consulta do Motivo da Transação Devolvida | D10: API Integration Lab
B11: 80 | C11: B2B | REST - Ordem de Transferência Internacional Pontual | D11: API Integration Lab
B12: 90 | C12: B2B | REST - Ficheiros C2B (Ficheiro de Pagamentos e Cobranças) | D12: API Integration Lab
B13: 100 | C13: B2B | REST - Listagem de Ficheiros de Retorno | D13: API Integration Lab
B14: 110 | C14: B2B | REST - Erros de Ficheiro | D14: API Integration Lab
B15: 120 | C15: B2B | REST - Detalhe das transferencias recebidas OIC | D15: API Integration Lab
... B22: 10 | C22: Melhorias | Consulta de Movimentos | Pesquisa por data e/ou descritivo | Adicionar saldo após movimento | D22: Best Site & App Lab
B23: 20 | C23: Melhorias | Transferências com referências de câmbio negociadas | Conta suporte diferente da(s) conta(s) da operação | Regras de visibilidade das referências | D23: Best Site & App Lab | G23: Migrar Clientes
B24: 30 | C24: Ficheiro Excel com Pagamentos | D24: Best Site & App Lab | G24: Excel do Jorge
B25: 40 | C25: Nova jornada de Operadores pós-login | D25: Best Site & App Lab | G25: Revamp
B26: 50 | C26: Nova jornada para instalar Certificado Digital | D26: Best Site & App Lab
B27: 60 | C27: Nova jornada de ativação Via Verde | D27: Best Site & App Lab
B28: 70 | C28: Nova jornada de requisição de Cheques | D28: Best Site & App Lab | G28: P Planear
B29: 80 | C29: Pedir Cartão de Débito | D29: Best Site & App Lab
B30: 90 | C30: Melhorias | Transferências Entre as Minhas Contas | Agendamento | D30: Best Site & App Lab | G30: Retomar
B31: 100 | C31: Melhorias | Transferências Entre as Minhas Contas | Em divisas | Mais informação no detalhe da operação em Pendente e Histórico | D31: Best Site & App Lab | G31: Retomar
B32: 110 | C32: Melhorias | Consulta de Movimentos | Detalhe do movimento | Cartões | D32: Best Site & App Lab | G32: Retomar
B33: 120 | C33: Melhorias | beneficiários obrigatoriedade de input de dados | D33: Best Site & App Lab | G33: Retomar
B34: 130 | C34: ESTAFETAS VTM | AR016753 – REGISTO E GESTÃO | D34: Best Site & App Lab
B35: 10 | C35: PEDIDO DE ENCERRAMENTO DE CONTA | D35: CORE Lab
B36: 20 | C36: MDSE - FASE 4/5 (n gerentes) 5= US de melhoria | D36: CORE Lab | G36: US - Certidão
B37: 30 | C37: REGISTO E RECENSEAMENTO NÃO CLIENTES | D37: CORE Lab
B38: 40 | C38: REVAMP KYC DE EMPRESAS - FLUXO E DOCUMENTO | D38: CORE Lab
B39: 50 | C39: RECOLHA TIN ESTRANGEIROS - PR015128 | D39: CORE Lab
B40: 60 | C40: MOD | A SUA SUCURSAL DIGITAL - ENTREGA 1 | D40: CORE Lab
B41: 70 | C41: REVAMP CUSTOMER CARE C/ GETHELP | GENAI | D41: CORE Lab | G41: Meet | H41: Romulo
B42: 80 | C42: API SITUAÇÃO ATIVIDADE AUTORIDADE TRIBUTÁRIA - ACED e MDSE | D42: CORE Lab
B43: 90 | C43: NOVA JORNADA DE REGISTO INICIAL E RECENSEAMENTO | D43: CORE Lab
B44: 100 | C44: DAU - PEDIDO DE DECLARAÇÃO DE AUDITORES | D44: CORE Lab
B45: 120 | C45: INFORMADB | NOTIFY - AÇÕES INICIATIVA BANCO | D45: CORE Lab
B46: 130 | C46: ADR | OP PEND | AR016393 DAR AUTENTICAÇÃO FORTE (Declaração de Assunção de Risco) | D46: CORE Lab
B47: 140 | C47: ADR | OP PEND - DMFI & RAI | D47: CORE Lab
...

Sheet Overview Geral
B2: Navegar através de filtros
A3: Lab | B3: Numero | C3: Projeto | D3: Descrição | E3: Estado | F3: QUA | G3: PROD | H3: Observações | I3: Comentários Internos
A4: Credit | B4: 1 | C4: New UX/UI Supply Chain Financing for Suppliers | D4: Nova jornada digital de antecipação de Avisos de Pagamento por Fornecedores (Clientes e Não Clientes) | E4: =IF(COUNTIF('Em Curso'!$B:$B,B4)>0,"Em Curso",IF(COUNTIF(Planeados!$B:$B,B4)>0,"Planeados",IF(COUNTIF(Standby!$B:$B,B4)>0,"Standby",IF(COUNTIF('API integration Lab'!$B:$B,B4)>0,"API integration Lab","")))) -> Em Curso | F4: 46107 | G4: 46107 | H4: Certificação complexa pode impactar na data de passagem a produção e abertura a clientes (piloto)
A5: Core | B5: 2 | C5: API enhanced entity registry for non-Clients (COMPprofile) (1) | D5: Registo de empresas nacionais no CIS e respetivos comprovativos (1º use case Fornecedores não Clientes) | E5: =IF(COUNTIF('Em Curso'!$B:$B,B5)>0,"Em Curso",IF(COUNTIF(Planeados!$B:$B,B5)>0,"Planeados",IF(COUNTIF(Standby!$B:$B,B5)>0,"Standby",IF(COUNTIF('API integration Lab'!$B:$B,B5)>0,"API integration Lab","")))) -> Em Curso | F5: 46351 | G5: 46351 | H5: Falta certificar coerência de dados da API. Confrontar dados InformaDB com CRC ~1 semana a tempo integral | I5: FCA 11-03-2026: a acompanhar novamente a certificação FCA 27-01-2026: retirar do Back Log. Core LAB da apoio como Consultor
A6: Core | B6: 3 | C6: New website onboarding for Suppliers (non-Clients) (1) | D6: Registo e recenseamento de Fornecedores nacionais não Clientes no MSE – Confirming | E6: =IF(COUNTIF('Em Curso'!$B:$B,B6)>0,"Em Curso",IF(COUNTIF(Planeados!$B:$B,B6)>0,"Planeados",IF(COUNTIF(Standby!$B:$B,B6)>0,"Standby",IF(COUNTIF('API integration Lab'!$B:$B,B6)>0,"API integration Lab","")))) -> Em Curso | F6: Dez 25 | G6: 46107 | H6: Base (~75%) será reutilizado no revamp do novo Registo e Recenseamento ao MSE | I6: FCA 11-03-2026: Alterei PRD para Mar 26 FCA 27-01-2026: inicio de certificação. Mantem ida a PRD em FEV2026
A7: Credit | B7: 4 | C7: API integration on ERP – Confirming & Factoring files | D7: Ficheiros de retorno com informação de Factoring e Confirming (eventos kafka) | E7: =IF(COUNTIF('Em Curso'!$B:$B,B7)>0,"Em Curso",IF(COUNTIF(Planeados!$B:$B,B7)>0,"Planeados",IF(COUNTIF(Standby!$B:$B,B7)>0,"Standby",IF(COUNTIF('API integration Lab'!$B:$B,B7)>0,"API integration Lab","")))) -> Em Curso | G7: Abr 26 | H7: Novo serviço disponível para todos os canais
A8: Credit | B8: 5 | C8: New UI/UX Credit Details | D8: Nova área de consulta de produtos de crédito | E8: =IF(COUNTIF('Em Curso'!$B:$B,B8)>0,"Em Curso",IF(COUNTIF(Planeados!$B:$B,B8)>0,"Planeados",IF(COUNTIF(Standby!$B:$B,B8)>0,"Standby",IF(COUNTIF('API integration Lab'!$B:$B,B8)>0,"API integration Lab","")))) -> Em Curso | F8: 46048 | G8: 46107 | H8: Certificação complexa com eventual impactar na abertura a clientes
A9: Credit | B9: 6 | C9: Crédito Digital Tesouraria (Phase 2) | D9: Integração Valor Alternativo (ADS II) - Capacidade de oferta de conta proposta imediata de montante inferior | E9: =IF(COUNTIF('Em Curso'!$B:$B,B9)>0,"Em Curso",IF(COUNTIF(Planeados!$B:$B,B9)>0,"Planeados",IF(COUNTIF(Standby!$B:$B,B9)>0,"Standby",IF(COUNTIF('API integration Lab'!$B:$B,B9)>0,"API integration Lab","")))) -> Em Curso | G9: 46107 | H9: JML020226 - Desenvolvimento em curso
A10: Payments | B10: 7 | C10: Debit Card Request | D10: Jornada de aquisição de cartão de débito (E2E) | E10: =IF(COUNTIF('Em Curso'!$B:$B,B10)>0,"Em Curso",IF(COUNTIF(Planeados!$B:$B,B10)>0,"Planeados",IF(COUNTIF(Standby!$B:$B,B10)>0,"Standby",IF(COUNTIF('API integration Lab'!$B:$B,B10)>0,"API integration Lab","")))) -> Em Curso | F10: 46107 | G10: Abr 26 | H10: Atraso por realocação de recursos para Transferências imediatas e moratorias
A11: Best Site | B11: 8 | C11: CMBO – Content Management BackOffice | D11: Migração de conteúdos de Sharepoint c/ descontinuação da Plataforma SP | E11: =IF(COUNTIF('Em Curso'!$B:$B,B11)>0,"Em Curso",IF(COUNTIF(Planeados!$B:$B,B11)>0,"Planeados",IF(COUNTIF(Standby!$B:$B,B11)>0,"Standby",IF(COUNTIF('API integration Lab'!$B:$B,B11)>0,"API integration Lab","")))) -> Em Curso | F11: 46381 | G11: 46199 | H11: EN – Produção: Jun.26 ; PT - Producao Set 26 ; ES Producao Dez 26
A12: Core | B12: 9 | C12: COMPProfile : Back office + Onboarding and maintenance | D12: Com back office para tratamento e classificação de todos os dados recebidos das várias fontes. Gera pacotes de dados standardizados e documentos prontos a serem consumidos internamente. Pedido cria entidades em Central com arquivo de documentos | E12: =IF(COUNTIF('Em Curso'!$B:$B,B12)>0,"Em Curso",IF(COUNTIF(Planeados!$B:$B,B12)>0,"Planeados",IF(COUNTIF(Standby!$B:$B,B12)>0,"Standby",IF(COUNTIF('API integration Lab'!$B:$B,B12)>0,"API integration Lab","")))) -> Em Curso | F12: 46048 | G12: Fev 26 | I12: FCA 11-03-2026: está em PRD desde FEV
A13: Core | B13: 10 | C13: COMPProfile : Implementação “Notify” | D13: Promove ações e tarefas internas após notificação de alteração de dados criticos das Empresas | E13: =IF(COUNTIF('Em Curso'!$B:$B,B13)>0,"Em Curso",IF(COUNTIF(Planeados!$B:$B,B13)>0,"Planeados",IF(COUNTIF(Standby!$B:$B,B13)>0,"Standby",IF(COUNTIF('API integration Lab'!$B:$B,B13)>0,"API integration Lab","")))) -> Em Curso | F13: 46048 | G13: TBD | H13: Em avaliação integração com outras plataformas de gestão de dados das Empresas existente no do Banco
A14: Core | B14: 11 | C14: 100% Digital Account Closure | D14: Pedido de encerramento de conta no site de Empresas | E14: =IF(COUNTIF('Em Curso'!$B:$B,B14)>0,"Em Curso",IF(COUNTIF(Planeados!$B:$B,B14)>0,"Planeados",IF(COUNTIF(Standby!$B:$B,B14)>0,"Standby",IF(COUNTIF('API integration Lab'!$B:$B,B14)>0,"API integration Lab","")))) -> Em Curso | F14: 46107 | G14: 46204 | H14: Requisito legal – BdP | I14: FCA 09-03-2026: vai a QA a 12-03 FCA 30-01-2026: Holding, DEV suspendido por priorização de atividades FCA 27-01-2026: Avaliar com COFF se pode aguardar FCA 20-01-2025: está em standby
A15: Core | B15: 12 | C15: Company Data Maintenance Journey – Phase 3 – Email | D15: Jornada para Empresas com dados expirados Soc Quotas e Unipessoais Sócios pessoas singulares 1 assinatura apenas 1 gerente | E15: =IF(COUNTIF('Em Curso'!$B:$B,B15)>0,"Em Curso",IF(COUNTIF(Planeados!$B:$B,B15)>0,"Planeados",IF(COUNTIF(Standby!$B:$B,B15)>0,"Standby",IF(COUNTIF('API integration Lab'!$B:$B,B15)>0,"API integration Lab","")))) -> Em Curso | F15: 46351 | G15: 45992 | H15: Comunicar à Rede e Clientes até 15 Dez Retira ~20% dos casos das Sucursais Processo o WFMC em certificação pelo COM c/apoio DBDE | I15: FCA 20-01-2025: Subiu a PRD a 22-12-25. Sem WFMC/Envio por e-mail ao COM
A16: Core | B16: 13 | C16: Company Data Maintenance journey – Phase 4 – WFMC | D16: Melhorias e simplificação do scope Fase 3, inclui para 1 ou mais Gerentes, sem filtrar situação dos dados pessoais dos gerentes que intervenientes e com entrega de processo em WFMC | E16: =IF(COUNTIF('Em Curso'!$B:$B,B16)>0,"Em Curso",IF(COUNTIF(Planeados!$B:$B,B16)>0,"Planeados",IF(COUNTIF(Standby!$B:$B,B16)>0,"Standby",IF(COUNTIF('API integration Lab'!$B:$B,B16)>0,"API integration Lab","")))) -> Em Curso | F16: 46107 | G16: Abr 26 | H16: Cerca de 30% dos casos Assegurar processo entregue apenas no WFMC – certificação COM c/ Apoio DBDE Em Abr 26 - Após ter WFMC abrir solução a casos em que existam Gerentes intervneientes com dados expirados no Banco para atingir +45%
A17: Core | B17: 14 | C17: Customer CARE | C2C - acesso direto com chamada em contexto | D17: Chamada á entregue na PAM/iPAC aos Operadores da linha de Apoio com Dados do Cliente e da Empresa em Contexto. Permite assegurar ao Operador que o Cliente que pede a chamada foi autenticado e identificado no login ao MSE. | E17: =IF(COUNTIF('Em Curso'!$B:$B,B17)>0,"Em Curso",IF(COUNTIF(Planeados!$B:$B,B17)>0,"Planeados",IF(COUNTIF(Standby!$B:$B,B17)>0,"Standby",IF(COUNTIF('API integration Lab'!$B:$B,B17)>0,"API integration Lab","")))) -> Em Curso | F17: 46107 | G17: Abr 26 | H17: Disponível após login no site para todos os utilizadores | I17: FCA 09-03-2026: Em QA a 12-03 FCA 18-02-2026: Definido com Fernando Cavalheiro este MVP para acompanhar a atividade SE016484 da DBD com o desnevolvimento de criação do novo serviço C2C e entrega chamada na PAM
A18: Core | B18: 15 | C18: Crédito Avançar (50k) | D18: Venda remota com envio de documentos pelo iPac para assinatura digital em operações pendentes no MSE | E18: =IF(COUNTIF('Em Curso'!$B:$B,B18)>0,"Em Curso",IF(COUNTIF(Planeados!$B:$B,B18)>0,"Planeados",IF(COUNTIF(Standby!$B:$B,B18)>0,"Standby",IF(COUNTIF('API integration Lab'!$B:$B,B18)>0,"API integration Lab","")))) -> Planeados | F18: TBD | G18: TBD | H18: Depende da retirada do “Acordo de Preenchimento de Livrança” do contrato de crédito. Atenção! GT Livrança Digital
A19: Core | B19: 16 | C19: Smart Moove, TPA, Cartões de Débito, Depositos Prazo e Crédito | D19: Venda remota com envio de documentos pelo iPac para assinatura digital em operações pendentes no MSE | E19: =IF(COUNTIF('Em Curso'!$B:$B,B19)>0,"Em Curso",IF(COUNTIF(Planeados!$B:$B,B19)>0,"Planeados",IF(COUNTIF(Standby!$B:$B,B19)>0,"Standby",IF(COUNTIF('API integration Lab'!$B:$B,B19)>0,"API integration Lab","")))) -> Planeados | F19: Dez 25 | G19: Fev 26 | H19: Pronto para arrancar no go live | I19: FCA 09-03-2026: EM PRD FCA 13-02-2026: incluidos os DPs FCA 27-01-2026: Em certificação
A20: Core | B20: 17 | C20: Seguros (BNL 2.0) | D20: Venda remota com envio de documentos pelo iPac para assinatura digital em operações pendentes no MSE | E20: =IF(COUNTIF('Em Curso'!$B:$B,B20)>0,"Em Curso",IF(COUNTIF(Planeados!$B:$B,B20)>0,"Planeados",IF(COUNTIF(Standby!$B:$B,B20)>0,"Standby",IF(COUNTIF('API integration Lab'!$B:$B,B20)>0,"API integration Lab","")))) -> Planeados | I20: FCA 09-03-2026: EM PRD FCA 30-01-2026: go live com testes ao msm tempo dos produtos bancários. Certificação concluida até Mar 26 FCA 27-01-2026: Aguadar entrega serviços da AGEAS
A21: Best Site | B21: 19 | C21: M-Authenticator – Digital Certificate Alternative | D21: APP de autenticação forte | E21: =IF(COUNTIF('Em Curso'!$B:$B,B21)>0,"Em Curso",IF(COUNTIF(Planeados!$B:$B,B21)>0,"Planeados",IF(COUNTIF(Standby!$B:$B,B21)>0,"Standby",IF(COUNTIF('API integration Lab'!$B:$B,B21)>0,"API integration Lab","")))) -> Planeados | F21: 46199 | H21: Em fase de levantamento de requisitos
A22: Core | B22: 18 | C22: New website onboarding for All Clients | D22: Novo processo de registo inicial da Empresa e recenseamento de utilizadores no site de Empresas | E22: =IF(COUNTIF('Em Curso'!$B:$B,B22)>0,"Em Curso",IF(COUNTIF(Planeados!$B:$B,B22)>0,"Planeados",IF(COUNTIF(Standby!$B:$B,B22)>0,"Standby",IF(COUNTIF('API integration Lab'!$B:$B,B22)>0,"API integration Lab","")))) -> Planeados | F22: TBD | G22: TBD | H22: Revamp do Registo e Recenseamento para Clientes e Não Clientes - reaproveita processo fornecedores Confirming. Em fase de levantamento de requisitos
A23: Best Site | B23: 20 | C23: New CRM & Banners Management “PMDE” | D23: Plataforma de gestão de campanhas / banners no MSE | E23: =IF(COUNTIF('Em Curso'!$B:$B,B23)>0,"Em Curso",IF(COUNTIF(Planeados!$B:$B,B23)>0,"Planeados",IF(COUNTIF(Standby!$B:$B,B23)>0,"Standby",IF(COUNTIF('API integration Lab'!$B:$B,B23)>0,"API integration Lab","")))) -> Planeados | F23: Fev 26 | G23: Abr 26 | H23: Permite atuação direta (DBDE) e Campanhas CRM. Plataforma reutilizável para outros canais
A24: Core | B24: 21 | C24: Customer CARE | Revamp | D24: Apoio ao Cliente com FAQ´s geradas com o GenAI antes do Contacto com o Banco | E24: =IF(COUNTIF('Em Curso'!$B:$B,B24)>0,"Em Curso",IF(COUNTIF(Planeados!$B:$B,B24)>0,"Planeados",IF(COUNTIF(Standby!$B:$B,B24)>0,"Standby",IF(COUNTIF('API integration Lab'!$B:$B,B24)>0,"API integration Lab","")))) -> Planeados | F24: 46199 | G24: Set 26 | H24: WIP – Projeto em Azure: entrega em Dez | I24: FCA 13-02-2026: Calendarizado com AFA QA em Jun e PRD em Set FCA 27-01-2026: Quick WIN caiu. Arranca com C2C. Em especificação Azure e aguarda serviço C2C pela DBD FCA 20-01-2026: requer prioirzação no Labb e no IT
A25: Core | B25: 22 | C25: Digital Middle Office (MVP) | E25: =IF(COUNTIF('Em Curso'!$B:$B,B25)>0,"Em Curso",IF(COUNTIF(Planeados!$B:$B,B25)>0,"Planeados",IF(COUNTIF(Standby!$B:$B,B25)>0,"Standby",IF(COUNTIF('API integration Lab'!$B:$B,B25)>0,"API integration Lab","")))) -> Planeados | G25: 46199 | H25: Scope em conclusão: DTO/DBDE | I25: FCA 20-01-2026: WIP com DTO
A26: Core | B26: 23 | C26: Digital Middle Office (MVP 2) | D26: Novas funcionalidades | E26: =IF(COUNTIF('Em Curso'!$B:$B,B26)>0,"Em Curso",IF(COUNTIF(Planeados!$B:$B,B26)>0,"Planeados",IF(COUNTIF(Standby!$B:$B,B26)>0,"Standby",IF(COUNTIF('API integration Lab'!$B:$B,B26)>0,"API integration Lab","")))) -> Planeados | F26: TBD | G26: TBD | H26: Por definir | I26: 1
A27: Payments | B27: 24 | C27: New Pay-By Millennium | D27: Serviço de emissão de pedidos de pagamento | E27: =IF(COUNTIF('Em Curso'!$B:$B,B27)>0,"Em Curso",IF(COUNTIF(Planeados!$B:$B,B27)>0,"Planeados",IF(COUNTIF(Standby!$B:$B,B27)>0,"Standby",IF(COUNTIF('API integration Lab'!$B:$B,B27)>0,"API integration Lab","")))) -> Planeados | F27: Abr 26 | G27: 46199 | H27: Versão simplificada – apenas com Entidade Ref MB para testar conceito e time-to-market. A incluir no Contrato Único de Acquiring Digital
A28: Payments | B28: 25 | C28: Full Cards Servicing | D28: Gestão da carteira de cartões para as Empresa: Consulta de saldos, movimentos e extratos, carregamento (pré-pagos), cancelamento, e substituição de cartão | E28: =IF(COUNTIF('Em Curso'!$B:$B,B28)>0,"Em Curso",IF(COUNTIF(Planeados!$B:$B,B28)>0,"Planeados",IF(COUNTIF(Standby!$B:$B,B28)>0,"Standby",IF(COUNTIF('API integration Lab'!$B:$B,B28)>0,"API integration Lab","")))) -> Planeados | F28: 46199 | G28: 46229 | H28: A ausência de serviço pós-venda nos cartões tem sido referida frequentemente por Clientes e Sucursais (ex. M Refeição)
A29: Credit | B29: 26 | C29: Factoring - Digital notifications | D29: Processo de notificação digital de devedores de factoring (clientes) | E29: =IF(COUNTIF('Em Curso'!$B:$B,B29)>0,"Em Curso",IF(COUNTIF(Planeados!$B:$B,B29)>0,"Planeados",IF(COUNTIF(Standby!$B:$B,B29)>0,"Standby",IF(COUNTIF('API integration Lab'!$B:$B,B29)>0,"API integration Lab","")))) -> Planeados | F29: TBD | G29: TBD | H29: Falta ainda avaliação técnica das Equipas da PUCC e XFAC. JML020226 - US's e design concluidos
A30: Credit | B30: 27 | C30: Crédito Digital Avançar (Wave 1) | D30: Simulador incorporado no MSE com conexão direta ao SWOC através do Credit Experience | E30: =IF(COUNTIF('Em Curso'!$B:$B,B30)>0,"Em Curso",IF(COUNTIF(Planeados!$B:$B,B30)>0,"Planeados",IF(COUNTIF(Standby!$B:$B,B30)>0,"Standby",IF(COUNTIF('API integration Lab'!$B:$B,B30)>0,"API integration Lab","")))) -> Planeados | F30: Set 26 | G30: TBD | H30: Desenho da jornada digital até à entrega no Credit Experience e SWOC. Data condicionada pelas prioridades da equipa do Cred. Experience
A31: Credit | B31: 28 | C31: New UX/UI Supply Chain Financing for Buyers | D31: Reestruturação do Confirming para Compradores com mais e novas funcionalidades | E31: =IF(COUNTIF('Em Curso'!$B:$B,B31)>0,"Em Curso",IF(COUNTIF(Planeados!$B:$B,B31)>0,"Planeados",IF(COUNTIF(Standby!$B:$B,B31)>0,"Standby",IF(COUNTIF('API integration Lab'!$B:$B,B31)>0,"API integration Lab","")))) -> Standby | F31: TBD | H31: Por iniciar diagnostico e alocação de recursos
A32: Credit | B32: 29 | C32: Trade Finance and Guarantees | D32: Reestruturação da area com mais e melhores funcionalidades com destaque para a revisão do processo documental | E32: =IF(COUNTIF('Em Curso'!$B:$B,B32)>0,"Em Curso",IF(COUNTIF(Planeados!$B:$B,B32)>0,"Planeados",IF(COUNTIF(Standby!$B:$B,B32)>0,"Standby",IF(COUNTIF('API integration Lab'!$B:$B,B32)>0,"API integration Lab","")))) -> Standby | F32: TBD | H32: Por iniciar diagnostico e alocação de recursos
A33: Credit | B33: 30 | C33: Crédito Digital Avançar (Wave 2) | D33: Integração do modelo de decisão automática até 15K/25k | E33: =IF(COUNTIF('Em Curso'!$B:$B,B33)>0,"Em Curso",IF(COUNTIF(Planeados!$B:$B,B33)>0,"Planeados",IF(COUNTIF(Standby!$B:$B,B33)>0,"Standby",IF(COUNTIF('API integration Lab'!$B:$B,B33)>0,"API integration Lab","")))) -> Standby | F33: TBD | H33: A 2ª fase arranca após a entrega da 1ª. Estimamos 2/3 meses para desenvolvimento e passagem a prod.. Pressupõe alteração da peça contratual
A34: Credit | B34: 31 | C34: Crédito Digital Avançar (Wave 3) | D34: 100% digital, mas permitindo a omnicanalidade e status das operações para consulta no MSE | E34: =IF(COUNTIF('Em Curso'!$B:$B,B34)>0,"Em Curso",IF(COUNTIF(Planeados!$B:$B,B34)>0,"Planeados",IF(COUNTIF(Standby!$B:$B,B34)>0,"Standby",IF(COUNTIF('API integration Lab'!$B:$B,B34)>0,"API integration Lab","")))) -> Standby | F34: TBD | H34: Fase final que prevê uma jornada digital E2E com exceção da assinatura da livrança
A35: Credit | B35: 32 | C35: Factoring Revamp | D35: Reestruturação da jornada de factoring com melhorias nos serviços, com destaque para a área de devedores | E35: =IF(COUNTIF('Em Curso'!$B:$B,B35)>0,"Em Curso",IF(COUNTIF(Planeados!$B:$B,B35)>0,"Planeados",IF(COUNTIF(Standby!$B:$B,B35)>0,"Standby",IF(COUNTIF('API integration Lab'!$B:$B,B35)>0,"API integration Lab","")))) -> Standby | F35: TBD | H35: Por iniciar diagnóstico e alocação de recursos
A36: Credit | B36: 33 | C36: Leasing simulação e contratação | D36: Jornada E2E Leasing automóvel, imobiliário e mobiliário | E36: =IF(COUNTIF('Em Curso'!$B:$B,B36)>0,"Em Curso",IF(COUNTIF(Planeados!$B:$B,B36)>0,"Planeados",IF(COUNTIF(Standby!$B:$B,B36)>0,"Standby",IF(COUNTIF('API integration Lab'!$B:$B,B36)>0,"API integration Lab","")))) -> Standby | F36: TBD | H36: Por iniciar diagnóstico e alocação de recursos
A37: Core | B37: 34 | C37: Utilizadores - Gestão e novos recenseamentos | D37: Revamp e upgerade da gestão de utilizadores após login no MSE | E37: =IF(COUNTIF('Em Curso'!$B:$B,B37)>0,"Em Curso",IF(COUNTIF(Planeados!$B:$B,B37)>0,"Planeados",IF(COUNTIF(Standby!$B:$B,B37)>0,"Standby",IF(COUNTIF('API integration Lab'!$B:$B,B37)>0,"API integration Lab","")))) -> Standby | F37: TBD | G37: TBD | I37: FCA 27-01-2026: Shapping e Conceito por fechar com equipa do Site. Alocar Nuno Belo após
A38: Core | B38: 35 | C38: Registo completo no site -Face lift / upgrade | D38: Face lift da jornada de registo completo no Site de Empresas com inclusão de melhorias nomeadamente utilização do COMPPROFILE para obtenção dos dados da Empesa | E38: =IF(COUNTIF('Em Curso'!$B:$B,B38)>0,"Em Curso",IF(COUNTIF(Planeados!$B:$B,B38)>0,"Planeados",IF(COUNTIF(Standby!$B:$B,B38)>0,"Standby",IF(COUNTIF('API integration Lab'!$B:$B,B38)>0,"API integration Lab","")))) -> Standby | F38: TBD | G38: TBD | I38: FCA 27-01-2026: Shapping e Conceito por fechar com equipa do Site. Alocar Nuno Belo após
A39: Core | B39: 36 | C39: Company Data Maintenance Journey – Phase 5 | D39: Use case da Fase 4 + atualização de dados pessoais para todos os Gerentes intervenientes nas contas da Empresas | E39: =IF(COUNTIF('Em Curso'!$B:$B,B39)>0,"Em Curso",IF(COUNTIF(Planeados!$B:$B,B39)>0,"Planeados",IF(COUNTIF(Standby!$B:$B,B39)>0,"Standby",IF(COUNTIF('API integration Lab'!$B:$B,B39)>0,"API integration Lab","")))) -> Standby | F39: TBD | H39: Implica fluxo de atualização de dados pessoais dos Gerentes intervenientes nas contas (FIC P) ~60% coverage of uses cases | I39: FCA 20-01-2026: Retirqar do Back Log?? Faz sentido fase 5? Ou basta ter info/alarmistica a encaminhar Gerentes para atualização de dados na APP Particulares ou na Sucursal
A40: Best Site | B40: 37 | C40: M-Certificados | D40: Avaliar interesse em modernizar aplicativo ou encontrar nova forma de criar Certificados Digitais | E40: =IF(COUNTIF('Em Curso'!$B:$B,B40)>0,"Em Curso",IF(COUNTIF(Planeados!$B:$B,B40)>0,"Planeados",IF(COUNTIF(Standby!$B:$B,B40)>0,"Standby",IF(COUNTIF('API integration Lab'!$B:$B,B40)>0,"API integration Lab","")))) -> Standby | F40: TBD | H40: Fern. Cavalheiro: Avaliação técnica Jorge Rodrigues: Atualizar páginas públicas
A41: API | B41: 38 | C41: B2B – Evoluir de SOAP para “REST” | D41: Atualmente, a utilização de APIs baseadas em SOAP representa uma barreira para a integração com parceiros como Milestone e Atlar, afetando clientes como Qima (Certis PT) e Ophelos (Intrum PT). A migração para APIs REST é essencial para aumentar a adoção e facilitar a interoperabilidade com sistemas modernos. | E41: =IF(COUNTIF('Em Curso'!$B:$B,B41)>0,"Em Curso",IF(COUNTIF(Planeados!$B:$B,B41)>0,"Planeados",IF(COUNTIF(Standby!$B:$B,B41)>0,"Standby",IF(COUNTIF('API integration Lab'!$B:$B,B41)>0,"API integration Lab","")))) -> API integration Lab | F41: TBD | G41: Abr 26 | H41: User Story 921359: B2B | Alteração do Protocolo da Mensagem | Alteração da Mensagem de SOAP para REST
...

Sheet Em Curso
A2: DESENVOLVIMENTOS EM CURSO
A4: Lab | B4: Numero | C4: Projeto | D4: Descrição | E4: QUA | F4: PROD | G4: Observações
A5: Credit | B5: 1 | C5: New UX/UI Supply Chain Financing for Suppliers | D5: Nova jornada digital de antecipação de Avisos de Pagamento por Fornecedores (Clientes e Não Clientes) | E5: Dez 25 | F5: Mar 26 | G5: Certificação complexa pode impactar na data de passagem a produção e abertura a clientes (piloto)
A6: Core | B6: 2 | C6: API enhanced entity registry for non-Clients (COMPprofile) (1) | D6: Registo de empresas nacionais no CIS e respetivos comprovativos (1º use case Fornecedores não Clientes) | E6: Nov 25 | F6: Nov 25 | G6: FCA 27-01-2026: retirar do Back Log. Core LAB da apoio como Consultor Falta certificar coerência de dados da API. Confrontar dados InformaDB com CRC ~1 semana a tempo integral
A8: Core | B8: 3 | C8: New website onboarding for Suppliers (non-Clients) (1) | D8: Registo e recenseamento de Fornecedores nacionais não Clientes no MSE – Confirming | E8: Dez 25 | F8: Fev 26 | G8: FCA 27-01-2026: inicio de certificação. Mantem ida a PRD em FEV2026 Base (~75%) será reutilizado no revamp do novo Registo e Recenseamento ao MSE
A9: Credit | B9: 4 | C9: API integration on ERP – Confirming & Factoring files | D9: Ficheiros de retorno com informação de Factoring e Confirming (eventos kafka) | E9: Mar 26 | F9: Abr 26 | G9: Novo serviço disponível para todos os canais
B10: 5 | C10: New UI/UX Credit Details | D10: Nova área de consulta de produtos de crédito | E10: Dez 25 | F10: Mar 26 | G10: Certificação complexa com eventual impactar na abertura a clientes
B12: 6 | C12: Crédito Digital Tesouraria (Phase 2) | D12: Integração Valor Alternativo (ADS II) - Capacidade de oferta de conta proposta imediata de montante inferior | E12: Dec 25 | F12: Abr 26 | G12: JML020226 - Desenvolvimento em curso
A14: Payments | B14: 7 | C14: Debit Card Request | D14: Jornada de aquisição de cartão de débito (E2E) | E14: Mar 26 | F14: Abr 26 | G14: Atraso por realocação de recursos para Transferências imediatas e moratorias
A15: Best Site | B15: 8 | C15: CMBO – Content Management BackOffice | D15: Migração de conteúdos de Sharepoint c/ descontinuação da Plataforma SP | E15: Dec 25 | F15: Jun 26 | G15: EN – Produção: Jun.26 ; PT - Producao Set 26 ; ES Producao Dez 26
A16: Core | B16: 9 | C16: COMPProfile : Back office + Onboarding and maintenance | D16: Com back office para tratamento e classificação de todos os dados recebidos das várias fontes. Gera pacotes de dados standardizados e documentos prontos a serem consumidos internamente. Pedido cria entidades em Central com arquivo de documentos | E16: Jan 26
A17: Core | B17: 10 | C17: COMPProfile : Implementação “Notify” | D17: Promove ações e tarefas após notificação de alteração de dados criticos das Empresas | E17: Jan 26 | F17: TBD
A18: Core | B18: 11 | C18: 100% Digital Account Closure | D18: Encerramento de conta digital | E18: Dec 25 | F18: Abr 26 | G18: FCA 09-03-2026: vai a QA a 12-03 FCA 30-01-2026: Holding, DEV suspendido por priorização de atividades FCA 27-01-2026: Avaliar com COFF se pode aguardar FCA 20-01-2025: está em standby Requisito legal – BdP
B20: 12 | C20: Company Data Maintenance Journey – Phase 3 – Email | D20: Jornada para Empresas com dados expirados Soc Quotas e Unipessoais Sócios pessoas singulares 1 assinatura apenas 1 gerente | E20: Nov 25 | F20: Dez 25 | G20: FCA 20-01-2025: Subiu a PRD a 22-12-25. Sem WFMC/Envio por e-mail ao COM Comunicar à Rede e Clientes até 15 Dez Retira ~20% dos casos das Sucursais Processo o WFMC em certificação pelo COM c/apoio DBDE
B24: 13 | C24: Company Data Maintenance journey – Phase 4 – WFMC | D24: Fase 3 para 1 ou mais Gerentes e com entrega de processo em WFMC e/ou por e-mail | E24: Mar 26 | F24: Abr 26 | G24: Cerca de 30% dos casos Assegurar processo entregue apenas no WFMC – certificação COM c/ Apoio DBDE Em Abr 26 - Após ter WFMC abrir solução a casos em que existam Gerentes intervneientes com dados expirados no Banco para atingir +45%
B25: 14 | C25: Customer CARE | C2C - acesso direto com chamada em contexto | D25: Apos Login no MSE o Cliente pede chamada. Chamada é entregue na PAM/iPAC aos Operadores da Linha de Apoio com Dados do Cliente e da Empresa em contexto. Permite assegurar ao Operador que o Cliente que pede a chamada foi autenticado e identificado no login ao MSE | E25: Mar 26 | F25: Abr 26 | G25: FCA 09-03-2026: Em QA a 12-03 FCA 18-02-2026: Definido com Fernando Cavalheiro este MVP para acompanhar a atividade SE016484 da DBD com o desnevolvimento de criação do novo serviço C2C e entrega chamada na PAM

Sheet Planeados
A2: DESENVOLVIMENTOS PLANEADOS
A5: Lab | B5: Numero | C5: Projeto | D5: Descrição | E5: QUA | F5: PROD | G5: Observações
A6: Core | B6: 15 | C6: Venda remota com envio de documentos pelo iPac para assinatura digital em operações pendentes no MSE | D6: Crédito Avançar (50k) | E6: TBD | F6: TBD | G6: Depende da retirada do “Acordo de Preenchimento de Livrança” do contrato de crédito. Atenção! GT Livrança Digital
A7: Core | B7: 16 | D7: Smart Moove, TPA, Cartões de Débito, Depositos Prazo e Crédito | E7: Dez 25 | F7: Fev 26 | G7: FCA 09-03-2026: EM PRD FCA 13-02-2026: incluidos os DPs FCA 27-01-2026: Em certificação Pronto para arrancar no go live
A8: Core | B8: 17 | D8: Seguros (BNL 2.0) | G8: FCA 09-03-2026: EM PRD FCA 30-01-2026: go live com testes ao msm tempo dos produtos bancários. Certificação concluida até Mar 26 FCA 27-01-2026: Aguadar entrega serviços da AGEAS
A9: Best Site | B9: 19 | C9: M-Authenticator – Digital Certificate Alternative | D9: APP de autenticação forte | E9: Jun 26 | G9: Em fase de levantamento de requisitos
A10: Core | B10: 18 | C10: New website onboarding for All Clients | E10: TBD | F10: TBD | G10: Revamp do Registo e Recenseamento para Clientes e Não Clientes - reaproveita processo fornecedores Confirming. Em fase de levantamento de requisitos
A11: Best Site | B11: 20 | C11: New CRM & Banners Management “PMDE” | D11: Plataforma de gestão de campanhas / banners no MSE | E11: Fev 26 | F11: Abr 26 | G11: Permite atuação direta (DBDE) e Campanhas CRM. Plataforma reutilizável para outros canais
A12: Core | B12: 21 | C12: Customer CARE | Revamp | D12: Apoio ao Cliente com FAQ´s geradas com o GenAI antes do Contacto com o Banco | E12: Jun 26 | F12: Set 26 | G12: FCA 13-02-2026: Calendarizado com AFA QA em Jun e PRD em Set FCA 27-01-2026: Quick WIN caiu. Arranca com C2C. Em especificação Azure e aguarda serviço C2C pela DBD FCA 20-01-2026: requer prioirzação no Labb e no IT WIP – Projeto em Azure: entrega em Dez
A13: Core | B13: 22 | C13: Digital Middle Office (MVP) | E13: Jun 26 | F13: TBD | G13: FCA 20-01-2026: WIP com DTO Scope em conclusão: DTO/DBDE
A14: Core | B14: 23 | C14: Digital Middle Office (MVP 2) | D14: Novas funcionalidades | E14: TBD | F14: TBD | G14: Por definir
A15: Payments | B15: 24 | C15: New Pay-By Millennium | D15: Serviço de emissão de pedidos de pagamento | E15: Mar 26 | F15: Abr 26 | G15: Versão simplificada – apenas com Entidade Ref MB para testar conceito e time-to-market. A incluir no Contrato Único de Acquiring Digital
A16: Payments | B16: 25 | C16: Full Cards Servicing | D16: Gestão da carteira de cartões para as Empresa: Consulta de saldos, movimentos e extratos, carregamento (pré-pagos), cancelamento, e substituição de cartão | E16: Jun 26 | F16: Jul 26 | G16: A ausência de serviço pós-venda nos cartões tem sido referida frequentemente por Clientes e Sucursais (ex. M Refeição)
A17: Credit | B17: 26 | C17: Factoring - Digital notifications | D17: Processo de notificação digital de devedores de factoring (clientes) | E17: TBD | F17: TBD | G17: Falta ainda avaliação técnica das Equipas da PUCC e XFAC. JML020226 - US's e design concluidos
A18: Credit | B18: 27 | C18: Crédito Digital Avançar (Wave 1) | D18: Simulador incorporado no MSE com conexão direta ao SWOC através do Credit Experience | E18: Set 26 | F18: TBD | G18: Desenho da jornada digital até à entrega no Credit Experience e SWOC. Data condicionada pelas prioridades da equipa do Cred. Experience

Sheet Standby
A2: DESENVOLVIMENTOS POR PLANEAR & DETALHAR
A4: Lab | B4: Numero | C4: Projeto | D4: Descrição | E4: QUA | F4: PROD | G4: Observações
A5: Credit | B5: 28 | C5: New UX/UI Supply Chain Financing for Buyers | D5: Reestruturação do Confirming para Compradores com mais e novas funcionalidades | E5: TBD | G5: Por iniciar diagnostico e alocação de recursos
B6: 29 | C6: Trade Finance and Guarantees | D6: Reestruturação da area com mais e melhores funcionalidades com destaque para a revisão do processo documental | E6: TBD | G6: Por iniciar diagnostico e alocação de recursos
B7: 30 | C7: Crédito Digital Avançar (Wave 2) | D7: Integração do modelo de decisão automática até 15K/25k | E7: TBD | G7: A 2ª fase arranca após a entrega da 1ª. Estimamos 2/3 meses para desenvolvimento e passagem a prod.. Pressupõe alteração da peça contratual
B8: 31 | C8: Crédito Digital Avançar (Wave 3) | D8: 100% digital, mas permitindo a omnicanalidade e status das operações para consulta no MSE | E8: TBD | G8: Fase final que prevê uma jornada digital E2E com exceção da assinatura da livrança
B9: 32 | C9: Factoring Revamp | D9: Reestruturação da jornada de factoring com melhorias nos serviços, com destaque para a área de devedores | E9: TBD | G9: Por iniciar diagnóstico e alocação de recursos
B10: 33 | C10: Leasing simulação e contratação | D10: Jornada E2E Leasing automóvel, imobiliário e mobiliário | E10: TBD | G10: Por iniciar diagnóstico e alocação de recursos
A11: Core | B11: 34 | C11: Utilizadores - Gestão e novos recenseamentos | D11: Revamp e upgerade da gestão de utilizadores após login no MSE | E11: TBD | F11: TBD | G11: FCA 27-01-2026: Shapping e Conceito por fechar com equipa do Site. Alocar Nuno Belo após
B12: 35 | C12: Registo completo no site -Face lift / upgrade | D12: Face lift da jornada de registo completo no Site de Empresas com inclusão de melhorias nomeadamente utilização do COMPPROFILE para obtenção dos dados da Empesa | E12: TBD | F12: TBD | G12: FCA 27-01-2026: Shapping e Conceito por fechar com equipa do Site. Alocar Nuno Belo após
B13: 36 | C13: Company Data Maintenance Journey – Phase 5 | D13: Use case da Fase 4 + atualização de dados pessoais para todos os Gerentes intervenientes nas contas da Empresas | E13: TBD | G13: FCA 20-01-2026: Retirqar do Back Log?? Faz sentido fase 5? Ou basta ter info/alarmistica a encaminhar Gerentes para atualização de dados na APP Particulares ou na Sucursal Implica fluxo de atualização de dados pessoais dos Gerentes intervenientes nas contas (FIC P) ~60% coverage of uses cases
B14: 37 | C14: M-Certificados | D14: Avaliar interesse em modernizar aplicativo ou encontrar nova forma de criar Certificados Digitais | E14: TBD | G14: Fern. Cavalheiro: Avaliação técnica Jorge Rodrigues: Atualizar páginas públicas

Sheet API integration Lab
A2: API integration Lab
A4: Lab | B4: Number | C4: Projeto | D4: Descrição | E4: QUA | F4: PROD | G4: Observações
A5: API | B5: 38 | C5: B2B – Evoluir de SOAP para “REST” | D5: Atualmente, a utilização de APIs baseadas em SOAP representa uma barreira para a integração com parceiros como Milestone e Atlar, afetando clientes como Qima (Certis PT) e Ophelos (Intrum PT). A migração para APIs REST é essencial para aumentar a adoção e facilitar a interoperabilidade com sistemas modernos. | E5: TBD | F5: Abr 26 | G5: User Story 921359: B2B | Alteração do Protocolo da Mensagem | Alteração da Mensagem de SOAP para REST
B6: 39 | C6: B2B – ConfirmationCOPB na PSDC | D6: Permitir registar e monitorizar a utilização do serviço ConfirmationCOPB na PSDC, atualmente sem histórico por ser uma consulta e não uma transação. | E6: TBD | F6: TBD | G6: User Story 962042: B2B | Criação na PSDC | Criação de entrada do serviço ConfirmationCOPB
B7: 40 | C7: B2B – Transferência Nacional | Aceitar o IBAN além do NIB | D7: Pretende-se que a ordem de transferência nacional aceite também o IBAN da conta a creditar, além do NIB atualmente usado.O campo XferInfo.DepAcctIdTo.AcctId deverá permitir IBAN como alternativa ao NIB. | E7: TBD | F7: Fev 26 | G7: User Story 926458: B2B | Transferências | Passar a fazer transferências também por IBAN
B8: 41 | C8: B2B – Open banking PISP | D8: Permitir a execução de operações através de outros Bancos, em linha com o que é feito atualmente no iziBizi. | E8: TBD | F8: TBD | G8: User Story 956426: B2B | Criação de Serviços | PISP
B9: 42 | C9: B2B – Motivo Devolução TRFs | D9: Permitir a consulta do detalhe do motivo da devolução de uma transferência. Caso de uso: Solverde, que solicitou este serviço. | E9: TBD | F9: TBD | G9: User Story 966231: B2B | Transferências - Motivo devolução
B10: 43 | C10: B2B/MultiBancário Eventos Kafka | D10: Serviço que irá permitir integração nos ERP’s das empresas com protocolos de confirming, as mensagens sobre o estado atual das faturas | E10: TBD | F10: Mai 26
B11: 44 | C11: iziBizi – Refresh Tokens | D11: No MSE, após alteração da password, o token do lado do iziBizi não é atualizado. Isto bloqueia diariamente o acesso para utilizadores com iziBizi ativo. | E11: TBD | F11: TBD | G11: User Story 973193: iziBizi | Melhorias | Refresh Tokens
B12: 45 | C12: M-Contabilidade – Refresh Tokens | D12: No MSE, após alteração da password, o token do lado do M Contabilidade não é atualizado. Isto bloqueia diariamente o acesso para utilizadores com M Contabilidade ativo. | E12: TBD | F12: TBD | G12: User Story 973284: M Contabilidade| Melhorias | Refresh Tokens

Sheet Falta Migrar para o MSE
A2: Desativação do FEE -> Migração para MSE
A4: Áreas (1º Nível) | B4: To Do | C4: Feature | D4: Funcionalidades | E4: Owner | F4: DATA ENTREGA IT | G4: Descrição | H4: Esforço Estimado
A5: Dashboard | B5: 0.6 | C5: Alertas | D5: Revamp Total | E5: Pedro Mousinho | F5: TBD | G5: Subscrição e gestão do serviço de alertas | H5: 
C6: Notificações | G6: Nova área de notificações (alertas/emails/eventos, etc) | H6: 
C7: Banco Mail | D7: Extinção | E7: N/A | G7: Serviço de comunicação com Clientes (a descontinuar no âmbito do projeto Costumer CARE) | H7: -
C8: Open Banking | D8: Revamp Total | E8: Pedro Mousinho | F8: 30 Abr | G8: Jornada de adesão ao serviço de Open Banking. Atualizar tb pág. para incluir Bancos Espanhóis. | H8: 
C9: Configurações da Empresa | D9: Revamp Total | G9: Criação de Operadores
G10: Criação de Autorizadores e Gestão de Utilizadores
G11: Consulta código de adesão e regras de autorização;
E12: Pedro/Ricardo | F12: 46111 | G12: Ativação do Canal Direto/B2B Millennium API | H12: 
C13: Configurações do Utilizador | D13: App M Empresas; Gerir Contas Dados pessoais | E13: Beatriz Melo | F13: 46052 | G13: Gestão de Contas visíveis no site e na App; Personalização de nome de contas | H13: 
A14: Pagamentos | B14: 0.35 | C14: Serviços Especiais | G14: Serviços específicos para A. Execução, Solicitadores, Prestadores de serviços (Notários e Advogados); Acesso ao SIRC (Sistema Integrado de Recuperação de Crédito) | H14: 
C15: Pagamentos de Baixo Valor | D15: Extinção | E15: N/A | F15: 46096 | G15: Consulta de pagamentos Via Verde | H15: 
C16: Autorizações de Débitos Diretos | D16: Revamp Total | E16: Pedro | G16: Consulta e Gestão de Autorizações de Débito (DD SEPA) | H16: 
G17: Consulta e Gestão de Autorizações Business to Business (B2B) | H17: 
C18: Agendamentos | D18: Revamp Total | E18: Beatriz Melo | F18: 46096 | G18: Consulta e Gestão de operações agendadas | H18: 
C19: Pedido de Numerário | G19: Serviço de entrega de numerário (trocos) | H19: 
C20: Cheques | D20: Revamp Total | E20: Pedro | F20: 46096 | G20: Requisição | H20: 
G21: Imagens de cheques | H21: 
G22: Serviço de Gestão de Cheques | H22: 
A23: Recebimentos | B23: 0.33 | C23: Terminal Pag.to Automático | G23: Fechos de TPA e Taxas de Serviço Comerciante (TSC) Pedido de TPA TPA Analytics | H23: 
C24: IBANs Digitais | G24: Adesão, emissão e gestão de IBANs Digitais | H24: 
C25: Outras Operações | G25: Serviço de Recolha e Tratamento de Valores – Servilock; Consulta Faturas Processadas – LockBox | H25: 
A26: Cartões | B26: 0.29 | C26: Consultas | D26: Revamp Total | E26: Jorge | F26: 46052 | H26: 
C27: Alterar Limites | D27: Revamp Total | E27: Jorge | F27: 46052 | H27: 
C28: Via Verde | D28: Revamp Total | E28: Pedro | F28: 46096 | G28: Ativação e substituição de identificador da Via Verde | H28: 
C29: Pedido de Cartão de Crédito | G29: Pedido de cartão por via de email para a sucursal (Pretende-se desenvolver jornada de contratação E2E) | H29: 
A30: Créditos | C30: Factoring | D30: Por iniciar
C31: Confirming Compradores | D31: Por iniciar
C32: Outros financiamentos | D32: Por iniciar | G32: Crédito Avançar; Empréstimos, Contas correntes e Garantias Bancárias
A33: Investimentos | C33: Consultas: Outros investimentos | G33: Outros investimentos; carteira de titulos; Seguros de capitalização
A34: Internacional | B34: 0.75 | C34: Ordens de Pagamento | G34: Cheques, Consulta de Transferências | H34: 
C35: Cash Management | G35: Adesão ao serviço, gestão e transferências de fundos, pedido e recolha de ficheiros de extratos (MT940) | H35: 
C36: Operações Documentárias | G36: Abertura e gestão de operações CRIM e REDX | H36: 
C37: Operações Cambiais | G37: Acesso a plataforma de negociação RET, Compra de moeda (pedido para sucursal) e consulta de cotações | H37: 
A38: Seguros | B38: 1 | C38: Carteira | G38: Consulta de seguros em carteira | H38: 
A40: Ficheiros | B40: 0.67 | C40: Extratos | D40: Revamp Total | E40: Luis Boleto | G40: Pedido e consulta de extratos de conta, TPA, histórico de operações e agregação de comissões e portes | H40: 
C41: Comprovativos | D41: Revamp Total | E41: Luis Boleto | G41: Consulta de comprovativos de operações processadas através de ficheiro | H41: 
C42: Retornos | D42: Revamp Total | E42: Luis Boleto | G42: Consulta de ficheiros com informação do resultado da execução das operações
C43: Outras Operações | D43: Revamp Total | E43: Luis Boleto
...

Sheet Calendário IT (Semanal)
A1: Calendário IT — Plano de Desenvolvimentos 2026 | G1: Versão semanal (W01–W53) · dados da calendarização original · Semana atual: W25
A2: Legenda (fase): | H2: Em Research | L2: Em Escrita | P2: User Stories | T2: User Stories Escritas | X2: Em Design (Bliss) | AB2: Desenvolvimento IT | AF2: Certificação | AJ2: Produção | AN2: Semana atual
A3: Projeto | B3: PO | C3: Stakeholders (ex. DMPA, DTO…) | D3: Descrição do âmbito | E3: Data passagem a produção | F3: Comentário / PdS da semana | G3: Janeiro | L3: Fevereiro | P3: Março | T3: Abril | Y3: Maio | AC3: Junho | AG3: Julho | AL3: Agosto | AP3: Setembro | AT3: Outubro | AY3: Novembro | BC3: Dezembro
G4: W01 | H4: W02 | I4: W03 | J4: W04 | K4: W05 | L4: W06 | M4: W07 | N4: W08 | O4: W09 | P4: W10 | Q4: W11 | R4: W12 | S4: W13 | T4: W14 | U4: W15 | V4: W16 | W4: W17 | X4: W18 | Y4: W19 | Z4: W20 | AA4: W21 | AB4: W22 | AC4: W23 | AD4: W24 | AE4: W25 | AF4: W26 | AG4: W27 | AH4: W28 | AI4: W29 | AJ4: W30 | AK4: W31 | AL4: W32 | AM4: W33 | AN4: W34 | AO4: W35 | AP4: W36 | AQ4: W37 | AR4: W38 | AS4: W39 | AT4: W40 | AU4: W41 | AV4: W42 | AW4: W43 | AX4: W44 | AY4: W45 | AZ4: W46 | BA4: W47 | BB4: W48 | BC4: W49 | BD4: W50 | BE4: W51 | BF4: W52 | BG4: W53
A5: Confirming
A6: Consulta de créditos
A7: CDT - Valor Alternativo
A8: Recenseamento não clientes
A9: Transformação dos IML´s para 5512
A10: Modo de envio Ime|Urgente
A11: Cliente Aplauso
A12: Encerramento de conta digital
A13: Pedido de cartão de crédito (email)
A14: Cartões - A NOSSA OFERTA
A15: SAF-T - Upload de ficheiro
A16: Agenda 2.0
... A35: Notas: • Projetos, fases e datas reproduzidos da calendarização mensal original (sheet «Calendário IT», agora oculta), com os meses expandidos em semanas. • PO, Stakeholders, Descrição do âmbito, Data passagem a produção e Comentário/PdS ficam por preencher (sem fonte na sheet original) — a completar em coordenação com Pedro/Ivânia. • A fase «Produção» na grelha indica a passagem a produção. • Semana atual destacada a vermelho.
